{
 "cells": [
  {
   "cell_type": "markdown",
   "metadata": {},
   "source": [
    "# Tensorflow"
   ]
  },
  {
   "cell_type": "code",
   "execution_count": 2,
   "metadata": {},
   "outputs": [
    {
     "data": {
      "application/vnd.jupyter.widget-view+json": {
       "model_id": "4fcc6b84effb48319cb91d4e7982a568",
       "version_major": 2,
       "version_minor": 0
      },
      "text/plain": [
       "Map:   0%|          | 0/3668 [00:00<?, ? examples/s]"
      ]
     },
     "metadata": {},
     "output_type": "display_data"
    },
    {
     "data": {
      "application/vnd.jupyter.widget-view+json": {
       "model_id": "0204da824c3a42779f48d048dcea00bc",
       "version_major": 2,
       "version_minor": 0
      },
      "text/plain": [
       "Map:   0%|          | 0/408 [00:00<?, ? examples/s]"
      ]
     },
     "metadata": {},
     "output_type": "display_data"
    },
    {
     "data": {
      "application/vnd.jupyter.widget-view+json": {
       "model_id": "9c789a3aca4f4a088e34e929f048ed1a",
       "version_major": 2,
       "version_minor": 0
      },
      "text/plain": [
       "Map:   0%|          | 0/1725 [00:00<?, ? examples/s]"
      ]
     },
     "metadata": {},
     "output_type": "display_data"
    },
    {
     "name": "stderr",
     "output_type": "stream",
     "text": [
      "c:\\Users\\usuario\\anaconda3\\envs\\env_101\\Lib\\site-packages\\datasets\\arrow_dataset.py:410: FutureWarning: The output of `to_tf_dataset` will change when a passing single element list for `labels` or `columns` in the next datasets version. To return a tuple structure rather than dict, pass a single string.\n",
      "Old behaviour: columns=['a'], labels=['labels'] -> (tf.Tensor, tf.Tensor)  \n",
      "             : columns='a', labels='labels' -> (tf.Tensor, tf.Tensor)  \n",
      "New behaviour: columns=['a'],labels=['labels'] -> ({'a': tf.Tensor}, {'labels': tf.Tensor})  \n",
      "             : columns='a', labels='labels' -> (tf.Tensor, tf.Tensor) \n",
      "  warnings.warn(\n"
     ]
    }
   ],
   "source": [
    "from datasets import load_dataset\n",
    "from transformers import AutoTokenizer\n",
    "import numpy as np\n",
    "\n",
    "raw_datasets = load_dataset(\"glue\", \"mrpc\")\n",
    "checkpoint = \"bert-base-uncased\"\n",
    "tokenizer = AutoTokenizer.from_pretrained(checkpoint)\n",
    "\n",
    "def tokenize_dataset(dataset):\n",
    "    encoded = tokenizer(\n",
    "        dataset[\"sentence1\"],\n",
    "        dataset[\"sentence2\"],\n",
    "        max_length=128,\n",
    "        truncation=True,\n",
    "    )\n",
    "    return encoded.data\n",
    "\n",
    "tokenized_datasets = raw_datasets.map(tokenize_dataset, batched=True)\n",
    "\n",
    "train_dataset = tokenized_datasets[\"train\"].to_tf_dataset(\n",
    "    columns=[\"input_ids\", \"attention_mask\", \"token_type_ids\"],\n",
    "    label_cols=[\"label\"],\n",
    "    shuffle=True,\n",
    "    batch_size=8)\n",
    "\n",
    "validation_dataset = tokenized_datasets[\"validation\"].to_tf_dataset(\n",
    "    columns=[\"input_ids\", \"attention_mask\", \"token_type_ids\"],\n",
    "    label_cols=[\"label\"],\n",
    "    shuffle=True,\n",
    "    batch_size=8)"
   ]
  },
  {
   "cell_type": "code",
   "execution_count": 3,
   "metadata": {},
   "outputs": [
    {
     "ename": "InvalidArgumentError",
     "evalue": "{{function_node __wrapped__IteratorGetNext_output_types_4_device_/job:localhost/replica:0/task:0/device:CPU:0}} Error in user-defined function passed to MapDataset:3 transformation with iterator: Iterator::Root::Prefetch::ParallelMapV2::ParallelMapV2::Map: ValueError: all input arrays must have the same shape\nTraceback (most recent call last):\n\n  File \"c:\\Users\\usuario\\anaconda3\\envs\\env_101\\Lib\\site-packages\\tensorflow\\python\\ops\\script_ops.py\", line 268, in __call__\n    return func(device, token, args)\n           ^^^^^^^^^^^^^^^^^^^^^^^^^\n\n  File \"c:\\Users\\usuario\\anaconda3\\envs\\env_101\\Lib\\site-packages\\tensorflow\\python\\ops\\script_ops.py\", line 146, in __call__\n    outputs = self._call(device, args)\n              ^^^^^^^^^^^^^^^^^^^^^^^^\n\n  File \"c:\\Users\\usuario\\anaconda3\\envs\\env_101\\Lib\\site-packages\\tensorflow\\python\\ops\\script_ops.py\", line 153, in _call\n    ret = self._func(*args)\n          ^^^^^^^^^^^^^^^^^\n\n  File \"c:\\Users\\usuario\\anaconda3\\envs\\env_101\\Lib\\site-packages\\tensorflow\\python\\autograph\\impl\\api.py\", line 643, in wrapper\n    return func(*args, **kwargs)\n           ^^^^^^^^^^^^^^^^^^^^^\n\n  File \"c:\\Users\\usuario\\anaconda3\\envs\\env_101\\Lib\\site-packages\\datasets\\utils\\tf_utils.py\", line 99, in np_get_batch\n    batch = collate_fn(batch, **collate_fn_args)\n            ^^^^^^^^^^^^^^^^^^^^^^^^^^^^^^^^^^^^\n\n  File \"c:\\Users\\usuario\\anaconda3\\envs\\env_101\\Lib\\site-packages\\datasets\\utils\\tf_utils.py\", line 48, in minimal_tf_collate_fn\n    batch[k] = np.stack([f[k] for f in features])\n               ^^^^^^^^^^^^^^^^^^^^^^^^^^^^^^^^^^\n\n  File \"c:\\Users\\usuario\\anaconda3\\envs\\env_101\\Lib\\site-packages\\numpy\\core\\shape_base.py\", line 449, in stack\n    raise ValueError('all input arrays must have the same shape')\n\nValueError: all input arrays must have the same shape\n\n\n\t [[{{function_node __inference_fetch_function_51}}{{node EagerPyFunc}}]] [Op:IteratorGetNext] name: ",
     "output_type": "error",
     "traceback": [
      "\u001b[1;31m---------------------------------------------------------------------------\u001b[0m",
      "\u001b[1;31mInvalidArgumentError\u001b[0m                      Traceback (most recent call last)",
      "Cell \u001b[1;32mIn[3], line 1\u001b[0m\n\u001b[1;32m----> 1\u001b[0m \u001b[38;5;28mnext\u001b[39m(\u001b[38;5;28miter\u001b[39m(train_dataset))[\u001b[38;5;241m1\u001b[39m]\n",
      "File \u001b[1;32mc:\\Users\\usuario\\anaconda3\\envs\\env_101\\Lib\\site-packages\\tensorflow\\python\\data\\ops\\iterator_ops.py:826\u001b[0m, in \u001b[0;36mOwnedIterator.__next__\u001b[1;34m(self)\u001b[0m\n\u001b[0;32m    824\u001b[0m \u001b[38;5;28;01mdef\u001b[39;00m \u001b[38;5;21m__next__\u001b[39m(\u001b[38;5;28mself\u001b[39m):\n\u001b[0;32m    825\u001b[0m   \u001b[38;5;28;01mtry\u001b[39;00m:\n\u001b[1;32m--> 826\u001b[0m     \u001b[38;5;28;01mreturn\u001b[39;00m \u001b[38;5;28mself\u001b[39m\u001b[38;5;241m.\u001b[39m_next_internal()\n\u001b[0;32m    827\u001b[0m   \u001b[38;5;28;01mexcept\u001b[39;00m errors\u001b[38;5;241m.\u001b[39mOutOfRangeError:\n\u001b[0;32m    828\u001b[0m     \u001b[38;5;28;01mraise\u001b[39;00m \u001b[38;5;167;01mStopIteration\u001b[39;00m\n",
      "File \u001b[1;32mc:\\Users\\usuario\\anaconda3\\envs\\env_101\\Lib\\site-packages\\tensorflow\\python\\data\\ops\\iterator_ops.py:776\u001b[0m, in \u001b[0;36mOwnedIterator._next_internal\u001b[1;34m(self)\u001b[0m\n\u001b[0;32m    773\u001b[0m \u001b[38;5;66;03m# TODO(b/77291417): This runs in sync mode as iterators use an error status\u001b[39;00m\n\u001b[0;32m    774\u001b[0m \u001b[38;5;66;03m# to communicate that there is no more data to iterate over.\u001b[39;00m\n\u001b[0;32m    775\u001b[0m \u001b[38;5;28;01mwith\u001b[39;00m context\u001b[38;5;241m.\u001b[39mexecution_mode(context\u001b[38;5;241m.\u001b[39mSYNC):\n\u001b[1;32m--> 776\u001b[0m   ret \u001b[38;5;241m=\u001b[39m gen_dataset_ops\u001b[38;5;241m.\u001b[39miterator_get_next(\n\u001b[0;32m    777\u001b[0m       \u001b[38;5;28mself\u001b[39m\u001b[38;5;241m.\u001b[39m_iterator_resource,\n\u001b[0;32m    778\u001b[0m       output_types\u001b[38;5;241m=\u001b[39m\u001b[38;5;28mself\u001b[39m\u001b[38;5;241m.\u001b[39m_flat_output_types,\n\u001b[0;32m    779\u001b[0m       output_shapes\u001b[38;5;241m=\u001b[39m\u001b[38;5;28mself\u001b[39m\u001b[38;5;241m.\u001b[39m_flat_output_shapes)\n\u001b[0;32m    781\u001b[0m   \u001b[38;5;28;01mtry\u001b[39;00m:\n\u001b[0;32m    782\u001b[0m     \u001b[38;5;66;03m# Fast path for the case `self._structure` is not a nested structure.\u001b[39;00m\n\u001b[0;32m    783\u001b[0m     \u001b[38;5;28;01mreturn\u001b[39;00m \u001b[38;5;28mself\u001b[39m\u001b[38;5;241m.\u001b[39m_element_spec\u001b[38;5;241m.\u001b[39m_from_compatible_tensor_list(ret)  \u001b[38;5;66;03m# pylint: disable=protected-access\u001b[39;00m\n",
      "File \u001b[1;32mc:\\Users\\usuario\\anaconda3\\envs\\env_101\\Lib\\site-packages\\tensorflow\\python\\ops\\gen_dataset_ops.py:3113\u001b[0m, in \u001b[0;36miterator_get_next\u001b[1;34m(iterator, output_types, output_shapes, name)\u001b[0m\n\u001b[0;32m   3111\u001b[0m   \u001b[38;5;28;01mreturn\u001b[39;00m _result\n\u001b[0;32m   3112\u001b[0m \u001b[38;5;28;01mexcept\u001b[39;00m _core\u001b[38;5;241m.\u001b[39m_NotOkStatusException \u001b[38;5;28;01mas\u001b[39;00m e:\n\u001b[1;32m-> 3113\u001b[0m   _ops\u001b[38;5;241m.\u001b[39mraise_from_not_ok_status(e, name)\n\u001b[0;32m   3114\u001b[0m \u001b[38;5;28;01mexcept\u001b[39;00m _core\u001b[38;5;241m.\u001b[39m_FallbackException:\n\u001b[0;32m   3115\u001b[0m   \u001b[38;5;28;01mpass\u001b[39;00m\n",
      "File \u001b[1;32mc:\\Users\\usuario\\anaconda3\\envs\\env_101\\Lib\\site-packages\\tensorflow\\python\\framework\\ops.py:5983\u001b[0m, in \u001b[0;36mraise_from_not_ok_status\u001b[1;34m(e, name)\u001b[0m\n\u001b[0;32m   5981\u001b[0m \u001b[38;5;28;01mdef\u001b[39;00m \u001b[38;5;21mraise_from_not_ok_status\u001b[39m(e, name) \u001b[38;5;241m-\u001b[39m\u001b[38;5;241m>\u001b[39m NoReturn:\n\u001b[0;32m   5982\u001b[0m   e\u001b[38;5;241m.\u001b[39mmessage \u001b[38;5;241m+\u001b[39m\u001b[38;5;241m=\u001b[39m (\u001b[38;5;124m\"\u001b[39m\u001b[38;5;124m name: \u001b[39m\u001b[38;5;124m\"\u001b[39m \u001b[38;5;241m+\u001b[39m \u001b[38;5;28mstr\u001b[39m(name \u001b[38;5;28;01mif\u001b[39;00m name \u001b[38;5;129;01mis\u001b[39;00m \u001b[38;5;129;01mnot\u001b[39;00m \u001b[38;5;28;01mNone\u001b[39;00m \u001b[38;5;28;01melse\u001b[39;00m \u001b[38;5;124m\"\u001b[39m\u001b[38;5;124m\"\u001b[39m))\n\u001b[1;32m-> 5983\u001b[0m   \u001b[38;5;28;01mraise\u001b[39;00m core\u001b[38;5;241m.\u001b[39m_status_to_exception(e) \u001b[38;5;28;01mfrom\u001b[39;00m \u001b[38;5;28;01mNone\u001b[39;00m\n",
      "\u001b[1;31mInvalidArgumentError\u001b[0m: {{function_node __wrapped__IteratorGetNext_output_types_4_device_/job:localhost/replica:0/task:0/device:CPU:0}} Error in user-defined function passed to MapDataset:3 transformation with iterator: Iterator::Root::Prefetch::ParallelMapV2::ParallelMapV2::Map: ValueError: all input arrays must have the same shape\nTraceback (most recent call last):\n\n  File \"c:\\Users\\usuario\\anaconda3\\envs\\env_101\\Lib\\site-packages\\tensorflow\\python\\ops\\script_ops.py\", line 268, in __call__\n    return func(device, token, args)\n           ^^^^^^^^^^^^^^^^^^^^^^^^^\n\n  File \"c:\\Users\\usuario\\anaconda3\\envs\\env_101\\Lib\\site-packages\\tensorflow\\python\\ops\\script_ops.py\", line 146, in __call__\n    outputs = self._call(device, args)\n              ^^^^^^^^^^^^^^^^^^^^^^^^\n\n  File \"c:\\Users\\usuario\\anaconda3\\envs\\env_101\\Lib\\site-packages\\tensorflow\\python\\ops\\script_ops.py\", line 153, in _call\n    ret = self._func(*args)\n          ^^^^^^^^^^^^^^^^^\n\n  File \"c:\\Users\\usuario\\anaconda3\\envs\\env_101\\Lib\\site-packages\\tensorflow\\python\\autograph\\impl\\api.py\", line 643, in wrapper\n    return func(*args, **kwargs)\n           ^^^^^^^^^^^^^^^^^^^^^\n\n  File \"c:\\Users\\usuario\\anaconda3\\envs\\env_101\\Lib\\site-packages\\datasets\\utils\\tf_utils.py\", line 99, in np_get_batch\n    batch = collate_fn(batch, **collate_fn_args)\n            ^^^^^^^^^^^^^^^^^^^^^^^^^^^^^^^^^^^^\n\n  File \"c:\\Users\\usuario\\anaconda3\\envs\\env_101\\Lib\\site-packages\\datasets\\utils\\tf_utils.py\", line 48, in minimal_tf_collate_fn\n    batch[k] = np.stack([f[k] for f in features])\n               ^^^^^^^^^^^^^^^^^^^^^^^^^^^^^^^^^^\n\n  File \"c:\\Users\\usuario\\anaconda3\\envs\\env_101\\Lib\\site-packages\\numpy\\core\\shape_base.py\", line 449, in stack\n    raise ValueError('all input arrays must have the same shape')\n\nValueError: all input arrays must have the same shape\n\n\n\t [[{{function_node __inference_fetch_function_51}}{{node EagerPyFunc}}]] [Op:IteratorGetNext] name: "
     ]
    }
   ],
   "source": [
    "next(iter(train_dataset))[1]"
   ]
  },
  {
   "cell_type": "code",
   "execution_count": 4,
   "metadata": {},
   "outputs": [
    {
     "name": "stdout",
     "output_type": "stream",
     "text": [
      "WARNING:tensorflow:From c:\\Users\\usuario\\anaconda3\\envs\\env_101\\Lib\\site-packages\\tf_keras\\src\\losses.py:2976: The name tf.losses.sparse_softmax_cross_entropy is deprecated. Please use tf.compat.v1.losses.sparse_softmax_cross_entropy instead.\n",
      "\n",
      "WARNING:tensorflow:From c:\\Users\\usuario\\anaconda3\\envs\\env_101\\Lib\\site-packages\\tf_keras\\src\\backend.py:873: The name tf.get_default_graph is deprecated. Please use tf.compat.v1.get_default_graph instead.\n",
      "\n"
     ]
    },
    {
     "name": "stderr",
     "output_type": "stream",
     "text": [
      "All PyTorch model weights were used when initializing TFBertForSequenceClassification.\n",
      "\n",
      "Some weights or buffers of the TF 2.0 model TFBertForSequenceClassification were not initialized from the PyTorch model and are newly initialized: ['classifier.weight', 'classifier.bias']\n",
      "You should probably TRAIN this model on a down-stream task to be able to use it for predictions and inference.\n"
     ]
    },
    {
     "name": "stdout",
     "output_type": "stream",
     "text": [
      "WARNING:tensorflow:From c:\\Users\\usuario\\anaconda3\\envs\\env_101\\Lib\\site-packages\\tf_keras\\src\\optimizers\\__init__.py:317: The name tf.train.Optimizer is deprecated. Please use tf.compat.v1.train.Optimizer instead.\n",
      "\n"
     ]
    }
   ],
   "source": [
    "import tensorflow as tf\n",
    "from transformers import TFAutoModelForSequenceClassification\n",
    "\n",
    "checkpoint = 'bert-base-cased'\n",
    "model = TFAutoModelForSequenceClassification.from_pretrained(checkpoint, num_labels=2)\n",
    "loss = tf.keras.losses.SparseCategoricalCrossentropy(from_logits=True)\n",
    "model.compile(optimizer='adam', loss=loss)"
   ]
  },
  {
   "cell_type": "code",
   "execution_count": 5,
   "metadata": {},
   "outputs": [
    {
     "name": "stdout",
     "output_type": "stream",
     "text": [
      "Epoch 1/3\n",
      "WARNING:tensorflow:From c:\\Users\\usuario\\anaconda3\\envs\\env_101\\Lib\\site-packages\\tf_keras\\src\\utils\\tf_utils.py:492: The name tf.ragged.RaggedTensorValue is deprecated. Please use tf.compat.v1.ragged.RaggedTensorValue instead.\n",
      "\n"
     ]
    },
    {
     "ename": "InvalidArgumentError",
     "evalue": "Graph execution error:\n\nDetected at node EagerPyFunc defined at (most recent call last):\n<stack traces unavailable>\nError in user-defined function passed to MapDataset:3 transformation with iterator: Iterator::Root::Prefetch::ParallelMapV2::ParallelMapV2::Map: ValueError: all input arrays must have the same shape\nTraceback (most recent call last):\n\n  File \"c:\\Users\\usuario\\anaconda3\\envs\\env_101\\Lib\\site-packages\\tensorflow\\python\\ops\\script_ops.py\", line 268, in __call__\n    return func(device, token, args)\n           ^^^^^^^^^^^^^^^^^^^^^^^^^\n\n  File \"c:\\Users\\usuario\\anaconda3\\envs\\env_101\\Lib\\site-packages\\tensorflow\\python\\ops\\script_ops.py\", line 146, in __call__\n    outputs = self._call(device, args)\n              ^^^^^^^^^^^^^^^^^^^^^^^^\n\n  File \"c:\\Users\\usuario\\anaconda3\\envs\\env_101\\Lib\\site-packages\\tensorflow\\python\\ops\\script_ops.py\", line 153, in _call\n    ret = self._func(*args)\n          ^^^^^^^^^^^^^^^^^\n\n  File \"c:\\Users\\usuario\\anaconda3\\envs\\env_101\\Lib\\site-packages\\tensorflow\\python\\autograph\\impl\\api.py\", line 643, in wrapper\n    return func(*args, **kwargs)\n           ^^^^^^^^^^^^^^^^^^^^^\n\n  File \"c:\\Users\\usuario\\anaconda3\\envs\\env_101\\Lib\\site-packages\\datasets\\utils\\tf_utils.py\", line 99, in np_get_batch\n    batch = collate_fn(batch, **collate_fn_args)\n            ^^^^^^^^^^^^^^^^^^^^^^^^^^^^^^^^^^^^\n\n  File \"c:\\Users\\usuario\\anaconda3\\envs\\env_101\\Lib\\site-packages\\datasets\\utils\\tf_utils.py\", line 48, in minimal_tf_collate_fn\n    batch[k] = np.stack([f[k] for f in features])\n               ^^^^^^^^^^^^^^^^^^^^^^^^^^^^^^^^^^\n\n  File \"c:\\Users\\usuario\\anaconda3\\envs\\env_101\\Lib\\site-packages\\numpy\\core\\shape_base.py\", line 449, in stack\n    raise ValueError('all input arrays must have the same shape')\n\nValueError: all input arrays must have the same shape\n\n\n\t [[{{node EagerPyFunc}}]]\n\t [[IteratorGetNext]] [Op:__inference_train_function_34760]",
     "output_type": "error",
     "traceback": [
      "\u001b[1;31m---------------------------------------------------------------------------\u001b[0m",
      "\u001b[1;31mInvalidArgumentError\u001b[0m                      Traceback (most recent call last)",
      "Cell \u001b[1;32mIn[5], line 1\u001b[0m\n\u001b[1;32m----> 1\u001b[0m model\u001b[38;5;241m.\u001b[39mfit(\n\u001b[0;32m      2\u001b[0m     train_dataset,\n\u001b[0;32m      3\u001b[0m     validation_data\u001b[38;5;241m=\u001b[39mvalidation_dataset,\n\u001b[0;32m      4\u001b[0m     epochs\u001b[38;5;241m=\u001b[39m\u001b[38;5;241m3\u001b[39m\n\u001b[0;32m      5\u001b[0m )\n",
      "File \u001b[1;32mc:\\Users\\usuario\\anaconda3\\envs\\env_101\\Lib\\site-packages\\transformers\\modeling_tf_utils.py:1229\u001b[0m, in \u001b[0;36mTFPreTrainedModel.fit\u001b[1;34m(self, *args, **kwargs)\u001b[0m\n\u001b[0;32m   1226\u001b[0m \u001b[38;5;129m@functools\u001b[39m\u001b[38;5;241m.\u001b[39mwraps(keras\u001b[38;5;241m.\u001b[39mModel\u001b[38;5;241m.\u001b[39mfit)\n\u001b[0;32m   1227\u001b[0m \u001b[38;5;28;01mdef\u001b[39;00m \u001b[38;5;21mfit\u001b[39m(\u001b[38;5;28mself\u001b[39m, \u001b[38;5;241m*\u001b[39margs, \u001b[38;5;241m*\u001b[39m\u001b[38;5;241m*\u001b[39mkwargs):\n\u001b[0;32m   1228\u001b[0m     args, kwargs \u001b[38;5;241m=\u001b[39m convert_batch_encoding(\u001b[38;5;241m*\u001b[39margs, \u001b[38;5;241m*\u001b[39m\u001b[38;5;241m*\u001b[39mkwargs)\n\u001b[1;32m-> 1229\u001b[0m     \u001b[38;5;28;01mreturn\u001b[39;00m \u001b[38;5;28msuper\u001b[39m()\u001b[38;5;241m.\u001b[39mfit(\u001b[38;5;241m*\u001b[39margs, \u001b[38;5;241m*\u001b[39m\u001b[38;5;241m*\u001b[39mkwargs)\n",
      "File \u001b[1;32mc:\\Users\\usuario\\anaconda3\\envs\\env_101\\Lib\\site-packages\\tf_keras\\src\\utils\\traceback_utils.py:70\u001b[0m, in \u001b[0;36mfilter_traceback.<locals>.error_handler\u001b[1;34m(*args, **kwargs)\u001b[0m\n\u001b[0;32m     67\u001b[0m     filtered_tb \u001b[38;5;241m=\u001b[39m _process_traceback_frames(e\u001b[38;5;241m.\u001b[39m__traceback__)\n\u001b[0;32m     68\u001b[0m     \u001b[38;5;66;03m# To get the full stack trace, call:\u001b[39;00m\n\u001b[0;32m     69\u001b[0m     \u001b[38;5;66;03m# `tf.debugging.disable_traceback_filtering()`\u001b[39;00m\n\u001b[1;32m---> 70\u001b[0m     \u001b[38;5;28;01mraise\u001b[39;00m e\u001b[38;5;241m.\u001b[39mwith_traceback(filtered_tb) \u001b[38;5;28;01mfrom\u001b[39;00m \u001b[38;5;28;01mNone\u001b[39;00m\n\u001b[0;32m     71\u001b[0m \u001b[38;5;28;01mfinally\u001b[39;00m:\n\u001b[0;32m     72\u001b[0m     \u001b[38;5;28;01mdel\u001b[39;00m filtered_tb\n",
      "File \u001b[1;32mc:\\Users\\usuario\\anaconda3\\envs\\env_101\\Lib\\site-packages\\tensorflow\\python\\eager\\execute.py:53\u001b[0m, in \u001b[0;36mquick_execute\u001b[1;34m(op_name, num_outputs, inputs, attrs, ctx, name)\u001b[0m\n\u001b[0;32m     51\u001b[0m \u001b[38;5;28;01mtry\u001b[39;00m:\n\u001b[0;32m     52\u001b[0m   ctx\u001b[38;5;241m.\u001b[39mensure_initialized()\n\u001b[1;32m---> 53\u001b[0m   tensors \u001b[38;5;241m=\u001b[39m pywrap_tfe\u001b[38;5;241m.\u001b[39mTFE_Py_Execute(ctx\u001b[38;5;241m.\u001b[39m_handle, device_name, op_name,\n\u001b[0;32m     54\u001b[0m                                       inputs, attrs, num_outputs)\n\u001b[0;32m     55\u001b[0m \u001b[38;5;28;01mexcept\u001b[39;00m core\u001b[38;5;241m.\u001b[39m_NotOkStatusException \u001b[38;5;28;01mas\u001b[39;00m e:\n\u001b[0;32m     56\u001b[0m   \u001b[38;5;28;01mif\u001b[39;00m name \u001b[38;5;129;01mis\u001b[39;00m \u001b[38;5;129;01mnot\u001b[39;00m \u001b[38;5;28;01mNone\u001b[39;00m:\n",
      "\u001b[1;31mInvalidArgumentError\u001b[0m: Graph execution error:\n\nDetected at node EagerPyFunc defined at (most recent call last):\n<stack traces unavailable>\nError in user-defined function passed to MapDataset:3 transformation with iterator: Iterator::Root::Prefetch::ParallelMapV2::ParallelMapV2::Map: ValueError: all input arrays must have the same shape\nTraceback (most recent call last):\n\n  File \"c:\\Users\\usuario\\anaconda3\\envs\\env_101\\Lib\\site-packages\\tensorflow\\python\\ops\\script_ops.py\", line 268, in __call__\n    return func(device, token, args)\n           ^^^^^^^^^^^^^^^^^^^^^^^^^\n\n  File \"c:\\Users\\usuario\\anaconda3\\envs\\env_101\\Lib\\site-packages\\tensorflow\\python\\ops\\script_ops.py\", line 146, in __call__\n    outputs = self._call(device, args)\n              ^^^^^^^^^^^^^^^^^^^^^^^^\n\n  File \"c:\\Users\\usuario\\anaconda3\\envs\\env_101\\Lib\\site-packages\\tensorflow\\python\\ops\\script_ops.py\", line 153, in _call\n    ret = self._func(*args)\n          ^^^^^^^^^^^^^^^^^\n\n  File \"c:\\Users\\usuario\\anaconda3\\envs\\env_101\\Lib\\site-packages\\tensorflow\\python\\autograph\\impl\\api.py\", line 643, in wrapper\n    return func(*args, **kwargs)\n           ^^^^^^^^^^^^^^^^^^^^^\n\n  File \"c:\\Users\\usuario\\anaconda3\\envs\\env_101\\Lib\\site-packages\\datasets\\utils\\tf_utils.py\", line 99, in np_get_batch\n    batch = collate_fn(batch, **collate_fn_args)\n            ^^^^^^^^^^^^^^^^^^^^^^^^^^^^^^^^^^^^\n\n  File \"c:\\Users\\usuario\\anaconda3\\envs\\env_101\\Lib\\site-packages\\datasets\\utils\\tf_utils.py\", line 48, in minimal_tf_collate_fn\n    batch[k] = np.stack([f[k] for f in features])\n               ^^^^^^^^^^^^^^^^^^^^^^^^^^^^^^^^^^\n\n  File \"c:\\Users\\usuario\\anaconda3\\envs\\env_101\\Lib\\site-packages\\numpy\\core\\shape_base.py\", line 449, in stack\n    raise ValueError('all input arrays must have the same shape')\n\nValueError: all input arrays must have the same shape\n\n\n\t [[{{node EagerPyFunc}}]]\n\t [[IteratorGetNext]] [Op:__inference_train_function_34760]"
     ]
    }
   ],
   "source": [
    "model.fit(\n",
    "    train_dataset,\n",
    "    validation_data=validation_dataset,\n",
    "    epochs=3\n",
    ")"
   ]
  },
  {
   "cell_type": "code",
   "execution_count": null,
   "metadata": {},
   "outputs": [],
   "source": []
  },
  {
   "cell_type": "code",
   "execution_count": null,
   "metadata": {},
   "outputs": [],
   "source": []
  },
  {
   "cell_type": "code",
   "execution_count": null,
   "metadata": {},
   "outputs": [],
   "source": []
  },
  {
   "cell_type": "code",
   "execution_count": null,
   "metadata": {},
   "outputs": [],
   "source": []
  },
  {
   "cell_type": "code",
   "execution_count": null,
   "metadata": {},
   "outputs": [],
   "source": []
  },
  {
   "cell_type": "code",
   "execution_count": null,
   "metadata": {},
   "outputs": [],
   "source": []
  },
  {
   "cell_type": "code",
   "execution_count": null,
   "metadata": {},
   "outputs": [],
   "source": []
  },
  {
   "cell_type": "code",
   "execution_count": null,
   "metadata": {},
   "outputs": [],
   "source": []
  },
  {
   "cell_type": "code",
   "execution_count": null,
   "metadata": {},
   "outputs": [],
   "source": []
  },
  {
   "cell_type": "markdown",
   "metadata": {},
   "source": []
  }
 ],
 "metadata": {
  "kernelspec": {
   "display_name": "env_101",
   "language": "python",
   "name": "python3"
  },
  "language_info": {
   "codemirror_mode": {
    "name": "ipython",
    "version": 3
   },
   "file_extension": ".py",
   "mimetype": "text/x-python",
   "name": "python",
   "nbconvert_exporter": "python",
   "pygments_lexer": "ipython3",
   "version": "3.11.9"
  }
 },
 "nbformat": 4,
 "nbformat_minor": 2
}
